Workbook

Sheet Table
E3: ="DROP TABLE "&Table!A4&";" -> DROP TABLE exc_poloniex;
A4: exc_poloniex | E4: =CONCATENATE("CREATE TABLE ",Table!A4,"(") -> CREATE TABLE exc_poloniex(
A5: id | B5: ="pk_"&Table!A5&"_"&Table!A4 -> pk_id_exc_poloniex | C5: VARCHAR(50) | E5: =IF(ISBLANK(Table!A5),")ENGINE=MyIsam;",IF(ISBLANK(#REF!),CONCATENATE(Table!A5," ",Table!C5,IF(ISBLANK(Table!B5),"",CONCATENATE(",CONSTRAINT ",Table!B5," PRIMARY KEY(",Table!A5,")",Table!D5,","))),CONCATENATE(Table!A5," ",Table!C5,IF(ISBLANK(Table!B5),",",CONCATENATE(",CONSTRAINT ",Table!B5," PRIMARY KEY(",Table!A5,")",Table!D5,","))))) -> id VARCHAR(50),CONSTRAINT pk_id_exc_poloniex PRIMARY KEY(id),
A6: aktif | C6: BOOLEAN | E6: =IF(ISBLANK(Table!A6),")ENGINE=Innodb;",IF(ISBLANK(Table!A7),CONCATENATE(Table!A6," ",Table!C6,IF(ISBLANK(Table!B6),"",CONCATENATE(",CONSTRAINT ",Table!B6," FOREIGN KEY(",Table!A6,") REFERENCES ",Table!D6,","))),CONCATENATE(Table!A6," ",Table!C6,IF(ISBLANK(Table!B6),",",CONCATENATE(",CONSTRAINT ",Table!B6," FOREIGN KEY(",Table!A6,") REFERENCES ",Table!D6,","))))) -> aktif BOOLEAN,
A7: currency | C7: VARCHAR(50) | E7: =IF(ISBLANK(Table!A7),")ENGINE=MyIsam;",IF(ISBLANK(#REF!),CONCATENATE(Table!A7," ",Table!C7,IF(ISBLANK(Table!B7),"",CONCATENATE(",CONSTRAINT ",Table!B7," PRIMARY KEY(",Table!A7,")",Table!D7,","))),CONCATENATE(Table!A7," ",Table!C7,IF(ISBLANK(Table!B7),",",CONCATENATE(",CONSTRAINT ",Table!B7," PRIMARY KEY(",Table!A7,")",Table!D7,","))))) -> currency VARCHAR(50),
A8: alias_currency | C8: VARCHAR(100) | E8: =IF(ISBLANK(Table!A8),")ENGINE=Innodb;",IF(ISBLANK(Table!A9),CONCATENATE(Table!A8," ",Table!C8,IF(ISBLANK(Table!B8),"",CONCATENATE(",CONSTRAINT ",Table!B8," FOREIGN KEY(",Table!A8,") REFERENCES ",Table!D8,","))),CONCATENATE(Table!A8," ",Table!C8,IF(ISBLANK(Table!B8),",",CONCATENATE(",CONSTRAINT ",Table!B8," FOREIGN KEY(",Table!A8,") REFERENCES ",Table!D8,","))))) -> alias_currency VARCHAR(100),
A9: base | C9: VARCHAR(50) | E9: =IF(ISBLANK(Table!A9),")ENGINE=Innodb;",IF(ISBLANK(Table!A10),CONCATENATE(Table!A9," ",Table!C9,IF(ISBLANK(Table!B9),"",CONCATENATE(",CONSTRAINT ",Table!B9," FOREIGN KEY(",Table!A9,") REFERENCES ",Table!D9,","))),CONCATENATE(Table!A9," ",Table!C9,IF(ISBLANK(Table!B9),",",CONCATENATE(",CONSTRAINT ",Table!B9," FOREIGN KEY(",Table!A9,") REFERENCES ",Table!D9,","))))) -> base VARCHAR(50),
A10: alias_base | C10: VARCHAR(100) | E10: =IF(ISBLANK(Table!A10),")ENGINE=Innodb;",IF(ISBLANK(Table!A11),CONCATENATE(Table!A10," ",Table!C10,IF(ISBLANK(Table!B10),"",CONCATENATE(",CONSTRAINT ",Table!B10," FOREIGN KEY(",Table!A10,") REFERENCES ",Table!D10,","))),CONCATENATE(Table!A10," ",Table!C10,IF(ISBLANK(Table!B10),",",CONCATENATE(",CONSTRAINT ",Table!B10," FOREIGN KEY(",Table!A10,") REFERENCES ",Table!D10,","))))) -> alias_base VARCHAR(100),
A11: bid | C11: DECIMAL(65,8) | E11: =IF(ISBLANK(Table!A11),")ENGINE=Innodb;",IF(ISBLANK(Table!A12),CONCATENATE(Table!A11," ",Table!C11,IF(ISBLANK(Table!B11),"",CONCATENATE(",CONSTRAINT ",Table!B11," FOREIGN KEY(",Table!A11,") REFERENCES ",Table!D11,","))),CONCATENATE(Table!A11," ",Table!C11,IF(ISBLANK(Table!B11),",",CONCATENATE(",CONSTRAINT ",Table!B11," FOREIGN KEY(",Table!A11,") REFERENCES ",Table!D11,","))))) -> bid DECIMAL(65,8),
A12: ask | C12: DECIMAL(65,8) | E12: =IF(ISBLANK(Table!A12),")ENGINE=Innodb;",IF(ISBLANK(Table!A13),CONCATENATE(Table!A12," ",Table!C12,IF(ISBLANK(Table!B12),"",CONCATENATE(",CONSTRAINT ",Table!B12," FOREIGN KEY(",Table!A12,") REFERENCES ",Table!D12,","))),CONCATENATE(Table!A12," ",Table!C12,IF(ISBLANK(Table!B12),",",CONCATENATE(",CONSTRAINT ",Table!B12," FOREIGN KEY(",Table!A12,") REFERENCES ",Table!D12,","))))) -> ask DECIMAL(65,8),
A13: volume_btc | C13: DECIMAL(65,8) | E13: =IF(ISBLANK(Table!A13),")ENGINE=Innodb;",IF(ISBLANK(Table!A14),CONCATENATE(Table!A13," ",Table!C13,IF(ISBLANK(Table!B13),"",CONCATENATE(",CONSTRAINT ",Table!B13," FOREIGN KEY(",Table!A13,") REFERENCES ",Table!D13,","))),CONCATENATE(Table!A13," ",Table!C13,IF(ISBLANK(Table!B13),",",CONCATENATE(",CONSTRAINT ",Table!B13," FOREIGN KEY(",Table!A13,") REFERENCES ",Table!D13,","))))) -> volume_btc DECIMAL(65,8),
A14: volume_alt | C14: DECIMAL(65,8) | E14: =IF(ISBLANK(Table!A14),")ENGINE=Innodb;",IF(ISBLANK(Table!A15),CONCATENATE(Table!A14," ",Table!C14,IF(ISBLANK(Table!B14),"",CONCATENATE(",CONSTRAINT ",Table!B14," FOREIGN KEY(",Table!A14,") REFERENCES ",Table!D14,","))),CONCATENATE(Table!A14," ",Table!C14,IF(ISBLANK(Table!B14),",",CONCATENATE(",CONSTRAINT ",Table!B14," FOREIGN KEY(",Table!A14,") REFERENCES ",Table!D14,","))))) -> volume_alt DECIMAL(65,8),
A15: date_input | C15: DATETIME | E15: =IF(ISBLANK(Table!A15),")ENGINE=Innodb;",IF(ISBLANK(Table!A16),CONCATENATE(Table!A15," ",Table!C15,IF(ISBLANK(Table!B15),"",CONCATENATE(",CONSTRAINT ",Table!B15," FOREIGN KEY(",Table!A15,") REFERENCES ",Table!D15,","))),CONCATENATE(Table!A15," ",Table!C15,IF(ISBLANK(Table!B15),",",CONCATENATE(",CONSTRAINT ",Table!B15," FOREIGN KEY(",Table!A15,") REFERENCES ",Table!D15,","))))) -> date_input DATETIME,
A16: date_update | C16: DATETIME | E16: =IF(ISBLANK(Table!A16),")ENGINE=Innodb;",IF(ISBLANK(Table!A17),CONCATENATE(Table!A16," ",Table!C16,IF(ISBLANK(Table!B16),"",CONCATENATE(",CONSTRAINT ",Table!B16," FOREIGN KEY(",Table!A16,") REFERENCES ",Table!D16,","))),CONCATENATE(Table!A16," ",Table!C16,IF(ISBLANK(Table!B16),",",CONCATENATE(",CONSTRAINT ",Table!B16," FOREIGN KEY(",Table!A16,") REFERENCES ",Table!D16,","))))) -> date_update DATETIME,
A17: link | C17: VARCHAR(300) | E17: =IF(ISBLANK(Table!A17),")ENGINE=Innodb;",IF(ISBLANK(Table!A18),CONCATENATE(Table!A17," ",Table!C17,IF(ISBLANK(Table!B17),"",CONCATENATE(",CONSTRAINT ",Table!B17," FOREIGN KEY(",Table!A17,") REFERENCES ",Table!D17,","))),CONCATENATE(Table!A17," ",Table!C17,IF(ISBLANK(Table!B17),",",CONCATENATE(",CONSTRAINT ",Table!B17," FOREIGN KEY(",Table!A17,") REFERENCES ",Table!D17,","))))) -> link VARCHAR(300),
A18: status | C18: CHAR(1) | E18: =IF(ISBLANK(Table!A18),")ENGINE=Innodb;",IF(ISBLANK(Table!A19),CONCATENATE(Table!A18," ",Table!C18,IF(ISBLANK(Table!B18),"",CONCATENATE(",CONSTRAINT ",Table!B18," FOREIGN KEY(",Table!A18,") REFERENCES ",Table!D18,","))),CONCATENATE(Table!A18," ",Table!C18,IF(ISBLANK(Table!B18),",",CONCATENATE(",CONSTRAINT ",Table!B18," FOREIGN KEY(",Table!A18,") REFERENCES ",Table!D18,","))))) -> status CHAR(1),
A19: date_status | C19: DATETIME | E19: =IF(ISBLANK(Table!A19),")ENGINE=Innodb;",IF(ISBLANK(Table!A20),CONCATENATE(Table!A19," ",Table!C19,IF(ISBLANK(Table!B19),"",CONCATENATE(",CONSTRAINT ",Table!B19," FOREIGN KEY(",Table!A19,") REFERENCES ",Table!D19,","))),CONCATENATE(Table!A19," ",Table!C19,IF(ISBLANK(Table!B19),",",CONCATENATE(",CONSTRAINT ",Table!B19," FOREIGN KEY(",Table!A19,") REFERENCES ",Table!D19,","))))) -> date_status DATETIME,
A20: ket_status | C20: INT(3) | E20: =IF(ISBLANK(Table!A20),")ENGINE=Innodb;",IF(ISBLANK(Table!A22),CONCATENATE(Table!A20," ",Table!C20,IF(ISBLANK(Table!B20),"",CONCATENATE(",CONSTRAINT ",Table!B20," FOREIGN KEY(",Table!A20,") REFERENCES ",Table!D20,","))),CONCATENATE(Table!A20," ",Table!C20,IF(ISBLANK(Table!B20),",",CONCATENATE(",CONSTRAINT ",Table!B20," FOREIGN KEY(",Table!A20,") REFERENCES ",Table!D20,","))))) -> ket_status INT(3)
E21: =IF(ISBLANK(Table!A21),")ENGINE=Innodb;",IF(ISBLANK(Table!A23),CONCATENATE(Table!A21," ",Table!C21,IF(ISBLANK(Table!B21),"",CONCATENATE(",CONSTRAINT ",Table!B21," FOREIGN KEY(",Table!A21,") REFERENCES ",Table!D21,","))),CONCATENATE(Table!A21," ",Table!C21,IF(ISBLANK(Table!B21),",",CONCATENATE(",CONSTRAINT ",Table!B21," FOREIGN KEY(",Table!A21,") REFERENCES ",Table!D21,","))))) -> )ENGINE=Innodb;
E25: ="DROP TABLE "&Table!A26&";" -> DROP TABLE exc_bittrex;
A26: exc_bittrex | E26: =CONCATENATE("CREATE TABLE ",Table!A26,"(") -> CREATE TABLE exc_bittrex(
A27: id | B27: ="pk_"&Table!A27&"_"&Table!A26 -> pk_id_exc_bittrex | C27: VARCHAR(50) | E27: =IF(ISBLANK(Table!A27),")ENGINE=MyIsam;",IF(ISBLANK(#REF!),CONCATENATE(Table!A27," ",Table!C27,IF(ISBLANK(Table!B27),"",CONCATENATE(",CONSTRAINT ",Table!B27," PRIMARY KEY(",Table!A27,")",Table!D27,","))),CONCATENATE(Table!A27," ",Table!C27,IF(ISBLANK(Table!B27),",",CONCATENATE(",CONSTRAINT ",Table!B27," PRIMARY KEY(",Table!A27,")",Table!D27,","))))) -> id VARCHAR(50),CONSTRAINT pk_id_exc_bittrex PRIMARY KEY(id),
A28: aktif | C28: BOOLEAN | E28: =IF(ISBLANK(Table!A28),")ENGINE=Innodb;",IF(ISBLANK(Table!A29),CONCATENATE(Table!A28," ",Table!C28,IF(ISBLANK(Table!B28),"",CONCATENATE(",CONSTRAINT ",Table!B28," FOREIGN KEY(",Table!A28,") REFERENCES ",Table!D28,","))),CONCATENATE(Table!A28," ",Table!C28,IF(ISBLANK(Table!B28),",",CONCATENATE(",CONSTRAINT ",Table!B28," FOREIGN KEY(",Table!A28,") REFERENCES ",Table!D28,","))))) -> aktif BOOLEAN,
A29: currency | C29: VARCHAR(50) | E29: =IF(ISBLANK(Table!A29),")ENGINE=Innodb;",IF(ISBLANK(Table!A30),CONCATENATE(Table!A29," ",Table!C29,IF(ISBLANK(Table!B29),"",CONCATENATE(",CONSTRAINT ",Table!B29," FOREIGN KEY(",Table!A29,") REFERENCES ",Table!D29,","))),CONCATENATE(Table!A29," ",Table!C29,IF(ISBLANK(Table!B29),",",CONCATENATE(",CONSTRAINT ",Table!B29," FOREIGN KEY(",Table!A29,") REFERENCES ",Table!D29,","))))) -> currency VARCHAR(50),
A30: alias_currency | C30: VARCHAR(100) | E30: =IF(ISBLANK(Table!A30),")ENGINE=Innodb;",IF(ISBLANK(Table!A31),CONCATENATE(Table!A30," ",Table!C30,IF(ISBLANK(Table!B30),"",CONCATENATE(",CONSTRAINT ",Table!B30," FOREIGN KEY(",Table!A30,") REFERENCES ",Table!D30,","))),CONCATENATE(Table!A30," ",Table!C30,IF(ISBLANK(Table!B30),",",CONCATENATE(",CONSTRAINT ",Table!B30," FOREIGN KEY(",Table!A30,") REFERENCES ",Table!D30,","))))) -> alias_currency VARCHAR(100),
A31: base | C31: VARCHAR(50) | E31: =IF(ISBLANK(Table!A31),")ENGINE=Innodb;",IF(ISBLANK(Table!A32),CONCATENATE(Table!A31," ",Table!C31,IF(ISBLANK(Table!B31),"",CONCATENATE(",CONSTRAINT ",Table!B31," FOREIGN KEY(",Table!A31,") REFERENCES ",Table!D31,","))),CONCATENATE(Table!A31," ",Table!C31,IF(ISBLANK(Table!B31),",",CONCATENATE(",CONSTRAINT ",Table!B31," FOREIGN KEY(",Table!A31,") REFERENCES ",Table!D31,","))))) -> base VARCHAR(50),
A32: alias_base | C32: VARCHAR(100) | E32: =IF(ISBLANK(Table!A32),")ENGINE=Innodb;",IF(ISBLANK(Table!A33),CONCATENATE(Table!A32," ",Table!C32,IF(ISBLANK(Table!B32),"",CONCATENATE(",CONSTRAINT ",Table!B32," FOREIGN KEY(",Table!A32,") REFERENCES ",Table!D32,","))),CONCATENATE(Table!A32," ",Table!C32,IF(ISBLANK(Table!B32),",",CONCATENATE(",CONSTRAINT ",Table!B32," FOREIGN KEY(",Table!A32,") REFERENCES ",Table!D32,","))))) -> alias_base VARCHAR(100),
A33: bid | C33: DECIMAL(65,8) | E33: =IF(ISBLANK(Table!A33),")ENGINE=Innodb;",IF(ISBLANK(Table!A34),CONCATENATE(Table!A33," ",Table!C33,IF(ISBLANK(Table!B33),"",CONCATENATE(",CONSTRAINT ",Table!B33," FOREIGN KEY(",Table!A33,") REFERENCES ",Table!D33,","))),CONCATENATE(Table!A33," ",Table!C33,IF(ISBLANK(Table!B33),",",CONCATENATE(",CONSTRAINT ",Table!B33," FOREIGN KEY(",Table!A33,") REFERENCES ",Table!D33,","))))) -> bid DECIMAL(65,8),
A34: ask | C34: DECIMAL(65,8) | E34: =IF(ISBLANK(Table!A34),")ENGINE=Innodb;",IF(ISBLANK(Table!A36),CONCATENATE(Table!A34," ",Table!C34,IF(ISBLANK(Table!B34),"",CONCATENATE(",CONSTRAINT ",Table!B34," FOREIGN KEY(",Table!A34,") REFERENCES ",Table!D34,","))),CONCATENATE(Table!A34," ",Table!C34,IF(ISBLANK(Table!B34),",",CONCATENATE(",CONSTRAINT ",Table!B34," FOREIGN KEY(",Table!A34,") REFERENCES ",Table!D34,","))))) -> ask DECIMAL(65,8),
A35: volume_btc | C35: DECIMAL(65,8) | E35: =IF(ISBLANK(Table!A35),")ENGINE=Innodb;",IF(ISBLANK(Table!A36),CONCATENATE(Table!A35," ",Table!C35,IF(ISBLANK(Table!B35),"",CONCATENATE(",CONSTRAINT ",Table!B35," FOREIGN KEY(",Table!A35,") REFERENCES ",Table!D35,","))),CONCATENATE(Table!A35," ",Table!C35,IF(ISBLANK(Table!B35),",",CONCATENATE(",CONSTRAINT ",Table!B35," FOREIGN KEY(",Table!A35,") REFERENCES ",Table!D35,","))))) -> volume_btc DECIMAL(65,8),
A36: volume_alt | C36: DECIMAL(65,8) | E36: =IF(ISBLANK(Table!A36),")ENGINE=Innodb;",IF(ISBLANK(Table!A37),CONCATENATE(Table!A36," ",Table!C36,IF(ISBLANK(Table!B36),"",CONCATENATE(",CONSTRAINT ",Table!B36," FOREIGN KEY(",Table!A36,") REFERENCES ",Table!D36,","))),CONCATENATE(Table!A36," ",Table!C36,IF(ISBLANK(Table!B36),",",CONCATENATE(",CONSTRAINT ",Table!B36," FOREIGN KEY(",Table!A36,") REFERENCES ",Table!D36,","))))) -> volume_alt DECIMAL(65,8),
A37: openbuyorder | C37: INT(10) | E37: =IF(ISBLANK(Table!A37),")ENGINE=Innodb;",IF(ISBLANK(Table!A38),CONCATENATE(Table!A37," ",Table!C37,IF(ISBLANK(Table!B37),"",CONCATENATE(",CONSTRAINT ",Table!B37," FOREIGN KEY(",Table!A37,") REFERENCES ",Table!D37,","))),CONCATENATE(Table!A37," ",Table!C37,IF(ISBLANK(Table!B37),",",CONCATENATE(",CONSTRAINT ",Table!B37," FOREIGN KEY(",Table!A37,") REFERENCES ",Table!D37,","))))) -> openbuyorder INT(10),
A38: opensellorder | C38: INT(10) | E38: =IF(ISBLANK(Table!A38),")ENGINE=Innodb;",IF(ISBLANK(Table!A39),CONCATENATE(Table!A38," ",Table!C38,IF(ISBLANK(Table!B38),"",CONCATENATE(",CONSTRAINT ",Table!B38," FOREIGN KEY(",Table!A38,") REFERENCES ",Table!D38,","))),CONCATENATE(Table!A38," ",Table!C38,IF(ISBLANK(Table!B38),",",CONCATENATE(",CONSTRAINT ",Table!B38," FOREIGN KEY(",Table!A38,") REFERENCES ",Table!D38,","))))) -> opensellorder INT(10),
A39: date_input | C39: DATETIME | E39: =IF(ISBLANK(Table!A39),")ENGINE=Innodb;",IF(ISBLANK(Table!A40),CONCATENATE(Table!A39," ",Table!C39,IF(ISBLANK(Table!B39),"",CONCATENATE(",CONSTRAINT ",Table!B39," FOREIGN KEY(",Table!A39,") REFERENCES ",Table!D39,","))),CONCATENATE(Table!A39," ",Table!C39,IF(ISBLANK(Table!B39),",",CONCATENATE(",CONSTRAINT ",Table!B39," FOREIGN KEY(",Table!A39,") REFERENCES ",Table!D39,","))))) -> date_input DATETIME,
A40: date_update | C40: DATETIME | E40: =IF(ISBLANK(Table!A40),")ENGINE=Innodb;",IF(ISBLANK(Table!A41),CONCATENATE(Table!A40," ",Table!C40,IF(ISBLANK(Table!B40),"",CONCATENATE(",CONSTRAINT ",Table!B40," FOREIGN KEY(",Table!A40,") REFERENCES ",Table!D40,","))),CONCATENATE(Table!A40," ",Table!C40,IF(ISBLANK(Table!B40),",",CONCATENATE(",CONSTRAINT ",Table!B40," FOREIGN KEY(",Table!A40,") REFERENCES ",Table!D40,","))))) -> date_update DATETIME,
A41: link | C41: VARCHAR(300) | E41: =IF(ISBLANK(Table!A41),")ENGINE=Innodb;",IF(ISBLANK(Table!A42),CONCATENATE(Table!A41," ",Table!C41,IF(ISBLANK(Table!B41),"",CONCATENATE(",CONSTRAINT ",Table!B41," FOREIGN KEY(",Table!A41,") REFERENCES ",Table!D41,","))),CONCATENATE(Table!A41," ",Table!C41,IF(ISBLANK(Table!B41),",",CONCATENATE(",CONSTRAINT ",Table!B41," FOREIGN KEY(",Table!A41,") REFERENCES ",Table!D41,","))))) -> link VARCHAR(300),
A42: status | C42: CHAR(1) | E42: =IF(ISBLANK(Table!A42),")ENGINE=Innodb;",IF(ISBLANK(Table!A43),CONCATENATE(Table!A42," ",Table!C42,IF(ISBLANK(Table!B42),"",CONCATENATE(",CONSTRAINT ",Table!B42," FOREIGN KEY(",Table!A42,") REFERENCES ",Table!D42,","))),CONCATENATE(Table!A42," ",Table!C42,IF(ISBLANK(Table!B42),",",CONCATENATE(",CONSTRAINT ",Table!B42," FOREIGN KEY(",Table!A42,") REFERENCES ",Table!D42,","))))) -> status CHAR(1),
A43: date_status | C43: DATETIME | E43: =IF(ISBLANK(Table!A43),")ENGINE=Innodb;",IF(ISBLANK(Table!A44),CONCATENATE(Table!A43," ",Table!C43,IF(ISBLANK(Table!B43),"",CONCATENATE(",CONSTRAINT ",Table!B43," FOREIGN KEY(",Table!A43,") REFERENCES ",Table!D43,","))),CONCATENATE(Table!A43," ",Table!C43,IF(ISBLANK(Table!B43),",",CONCATENATE(",CONSTRAINT ",Table!B43," FOREIGN KEY(",Table!A43,") REFERENCES ",Table!D43,","))))) -> date_status DATETIME,
A44: ket_status | C44: INT(3) | E44: =IF(ISBLANK(Table!A44),")ENGINE=Innodb;",IF(ISBLANK(Table!A46),CONCATENATE(Table!A44," ",Table!C44,IF(ISBLANK(Table!B44),"",CONCATENATE(",CONSTRAINT ",Table!B44," FOREIGN KEY(",Table!A44,") REFERENCES ",Table!D44,","))),CONCATENATE(Table!A44," ",Table!C44,IF(ISBLANK(Table!B44),",",CONCATENATE(",CONSTRAINT ",Table!B44," FOREIGN KEY(",Table!A44,") REFERENCES ",Table!D44,","))))) -> ket_status INT(3)
E45: =IF(ISBLANK(Table!A45),")ENGINE=Innodb;",IF(ISBLANK(Table!A47),CONCATENATE(Table!A45," ",Table!C45,IF(ISBLANK(Table!B45),"",CONCATENATE(",CONSTRAINT ",Table!B45," FOREIGN KEY(",Table!A45,") REFERENCES ",Table!D45,","))),CONCATENATE(Table!A45," ",Table!C45,IF(ISBLANK(Table!B45),",",CONCATENATE(",CONSTRAINT ",Table!B45," FOREIGN KEY(",Table!A45,") REFERENCES ",Table!D45,","))))) -> )ENGINE=Innodb;
...

Sheet Function
A1: FUNCTION hitung_keuntungan
A2: DROP FUNCTION hitung_keuntungan;
A3: DELIMITER $$
A4: CREATE FUNCTION hitung_keuntungan (ask DECIMAL(60,8), bid DECIMAL(60,8))
A5: RETURNS DECIMAL(60,3)
A6: BEGIN
A7: DECLARE dist DECIMAL(60,3);
A8: IF (ask<bid) THEN SET dist =((GREATEST(bid,ask)-LEAST(bid,ask))/LEAST(bid,ask))*100;
A9: ELSEIF (ask>bid) THEN SET dist =-1*(((GREATEST(bid,ask)-LEAST(bid,ask))/LEAST(bid,ask))*100);
A10: ELSE SET dist=0;
A11: END IF;
A12: RETURN dist;
... A71: DELIMITER ;

Sheet PROCEDURE
A1: PROCEDURE hapusdataexpiry
A2: DROP PROCEDURE hapusdataexpiry;
A3: DELIMITER $$
A4: CREATE PROCEDURE hapusdataexpiry (ask INT(3))
A5: BEGIN
A6: DELETE FROM exc_bittrex WHERE ket_status=ask AND status='d';
A7: DELETE FROM exc_bleutrade WHERE ket_status=ask AND status='d';
A8: DELETE FROM exc_btce WHERE ket_status=ask AND status='d';
A9: DELETE FROM exc_ccex WHERE ket_status=ask AND status='d';
A10: DELETE FROM exc_cryptopia WHERE ket_status=ask AND status='d';
A11: DELETE FROM exc_poloniex WHERE ket_status=ask AND status='d';
A12: DELETE FROM exc_vipbtckoid WHERE ket_status=ask AND status='d';
... A53: DELIMITER ;

Sheet coretan query
A3: DROP TRIGGER test_beforeinsert;
A4: DELIMITER $$
A5: CREATE TRIGGER test_beforeinsert
A6: BEFORE INSERT ON test
A7: FOR EACH ROW
A8: BEGIN
A9: DECLARE dist VARCHAR(1000);
A10: SET dist=(SELECT od FROM test WHERE ID=new.ID LIMIT 1);
A11: IF(NEW.od IS NULL) THEN SET NEW.od=dist;END IF;
A13: END$$
A14: DELIMITER ;

Sheet TRIGGERS
A3: DELIMITER $$
A4: CREATE TRIGGER bdbbittrex_input
A5: BEFORE INSERT ON bdb_bittrex
A6: FOR EACH ROW
A7: BEGIN
A8: set NEW.id= SHA2(CONCAT(NEW.currency,NEW.alias_currency,NEW.date,NEW.type,NEW.rate,NEW.amount,NEW.total),256);
A9: set NEW.date= UNIX_TIMESTAMP(NEW.date);
A10: END$$
A11: DELIMITER ;
A16: DROP TRIGGER bdbpoloniex_input; | I16: set NEW.timestamp = UNIX_TIMESTAMP(TRIM(NEW.date);
A17: DELIMITER $$
A18: CREATE TRIGGER bdbpoloniex_input
A19: BEFORE INSERT ON bdb_poloniex | I19: set NEW.timestamp= UNIX_TIMESTAMP(NEW.date);
A20: FOR EACH ROW
A21: BEGIN
A22: set NEW.id= SHA2(CONCAT(NEW.currency,NEW.alias_currency,NEW.date,NEW.type,NEW.rate,NEW.amount,NEW.total),256);
A23: END$$
A24: DELIMITER ; | J24: set NEW.timestamp = SELECT UNIX_TIMESTAMP(date) FROM bdb_poloniex WHERE id=NEW.id;
A30: DROP TRIGGER bdbpoloniex_afterinsert;
A31: DELIMITER $$
A32: CREATE TRIGGER bdbpoloniex_afterinsert
A33: AFTER INSERT ON bdb_poloniex
A34: FOR EACH ROW
A35: BEGIN | D35: UPDATE bdb_poloniex SET timestamp = UNIX_TIMESTAMP(NEW.date) WHERE id=NEW.id;
A36: UPDATE bdb_poloniex SET timestamp = UNIX_TIMESTAMP(NEW.date) WHERE id=NEW.id;
A37: END$$
A43: DELIMITER ;
A44: CREATE TRIGGER bittrex_input
A45: BEFORE INSERT ON exc_bittrex
A46: FOR EACH ROW
A47: BEGIN
A48: set NEW.link= CONCAT('https://bittrex.com/Market/Index?MarketName=',NEW.base,'-',NEW.currency);
A49: SET NEW.date_input= NOW();
A50: END$$ | O50: id
O51: idcurrency
A52: CREATE TRIGGER bleutrade_input | O52: currency
A53: BEFORE INSERT ON exc_bleutrade | O53: alias_currency
A54: FOR EACH ROW | O54: date
A55: BEGIN | O55: type
A56: set NEW.link= CONCAT('https://bleutrade.com/exchange/',NEW.currency,'/',NEW.base); | O56: rate
...

Sheet Sheet9
A1: 8360 | C1: =CONCATENATE("wget --header='Accept-Language: en-us,en;q=0.5' -T 600 http://127.0.0.1/karbitexchanges/bitcointalk/tambah_announcementaltcoin?halaman=",Sheet9!A1," --delete-after") -> wget --header='Accept-Language: en-us,en;q=0.5' -T 600 http://127.0.0.1/karbitexchanges/bitcointalk/tambah_announcementaltcoin?halaman=8360 --delete-after | D1: =CONCATENATE("wget --header='Accept-Language: en-us,en;q=0.5' -T 600 http://127.0.0.1/karbitexchanges/bitcointalk/tambah_marketplacealtcoin?halaman=",Sheet9!L1," --delete-after") -> wget --header='Accept-Language: en-us,en;q=0.5' -T 600 http://127.0.0.1/karbitexchanges/bitcointalk/tambah_marketplacealtcoin?halaman=6840 --delete-after | E1: Sleep 60 | F1: Sleep 60 | L1: 6840
A2: =Sheet9!A1-40 -> 8320 | C2: =CONCATENATE("wget --header='Accept-Language: en-us,en;q=0.5' -T 600 http://127.0.0.1/karbitexchanges/bitcointalk/tambah_announcementaltcoin?halaman=",Sheet9!A2," --delete-after") -> wget --header='Accept-Language: en-us,en;q=0.5' -T 600 http://127.0.0.1/karbitexchanges/bitcointalk/tambah_announcementaltcoin?halaman=8320 --delete-after | D2: =CONCATENATE("wget --header='Accept-Language: en-us,en;q=0.5' -T 600 http://127.0.0.1/karbitexchanges/bitcointalk/tambah_marketplacealtcoin?halaman=",Sheet9!L2," --delete-after") -> wget --header='Accept-Language: en-us,en;q=0.5' -T 600 http://127.0.0.1/karbitexchanges/bitcointalk/tambah_marketplacealtcoin?halaman=6800 --delete-after | E2: Sleep 60 | F2: Sleep 60 | L2: =Sheet9!L1-40 -> 6800
A3: =Sheet9!A2-40 -> 8280 | C3: =CONCATENATE("wget --header='Accept-Language: en-us,en;q=0.5' -T 600 http://127.0.0.1/karbitexchanges/bitcointalk/tambah_announcementaltcoin?halaman=",Sheet9!A3," --delete-after") -> wget --header='Accept-Language: en-us,en;q=0.5' -T 600 http://127.0.0.1/karbitexchanges/bitcointalk/tambah_announcementaltcoin?halaman=8280 --delete-after | D3: =CONCATENATE("wget --header='Accept-Language: en-us,en;q=0.5' -T 600 http://127.0.0.1/karbitexchanges/bitcointalk/tambah_marketplacealtcoin?halaman=",Sheet9!L3," --delete-after") -> wget --header='Accept-Language: en-us,en;q=0.5' -T 600 http://127.0.0.1/karbitexchanges/bitcointalk/tambah_marketplacealtcoin?halaman=6760 --delete-after | E3: Sleep 61 | F3: Sleep 60 | L3: =Sheet9!L2-40 -> 6760
A4: =Sheet9!A3-40 -> 8240 | C4: =CONCATENATE("wget --header='Accept-Language: en-us,en;q=0.5' -T 600 http://127.0.0.1/karbitexchanges/bitcointalk/tambah_announcementaltcoin?halaman=",Sheet9!A4," --delete-after") -> wget --header='Accept-Language: en-us,en;q=0.5' -T 600 http://127.0.0.1/karbitexchanges/bitcointalk/tambah_announcementaltcoin?halaman=8240 --delete-after | D4: =CONCATENATE("wget --header='Accept-Language: en-us,en;q=0.5' -T 600 http://127.0.0.1/karbitexchanges/bitcointalk/tambah_marketplacealtcoin?halaman=",Sheet9!L4," --delete-after") -> wget --header='Accept-Language: en-us,en;q=0.5' -T 600 http://127.0.0.1/karbitexchanges/bitcointalk/tambah_marketplacealtcoin?halaman=6720 --delete-after | E4: Sleep 62 | F4: Sleep 60 | L4: =Sheet9!L3-40 -> 6720
A5: =Sheet9!A4-40 -> 8200 | C5: =CONCATENATE("wget --header='Accept-Language: en-us,en;q=0.5' -T 600 http://127.0.0.1/karbitexchanges/bitcointalk/tambah_announcementaltcoin?halaman=",Sheet9!A5," --delete-after") -> wget --header='Accept-Language: en-us,en;q=0.5' -T 600 http://127.0.0.1/karbitexchanges/bitcointalk/tambah_announcementaltcoin?halaman=8200 --delete-after | D5: =CONCATENATE("wget --header='Accept-Language: en-us,en;q=0.5' -T 600 http://127.0.0.1/karbitexchanges/bitcointalk/tambah_marketplacealtcoin?halaman=",Sheet9!L5," --delete-after") -> wget --header='Accept-Language: en-us,en;q=0.5' -T 600 http://127.0.0.1/karbitexchanges/bitcointalk/tambah_marketplacealtcoin?halaman=6680 --delete-after | E5: Sleep 63 | F5: Sleep 60 | L5: =Sheet9!L4-40 -> 6680
A6: =Sheet9!A5-40 -> 8160 | C6: =CONCATENATE("wget --header='Accept-Language: en-us,en;q=0.5' -T 600 http://127.0.0.1/karbitexchanges/bitcointalk/tambah_announcementaltcoin?halaman=",Sheet9!A6," --delete-after") -> wget --header='Accept-Language: en-us,en;q=0.5' -T 600 http://127.0.0.1/karbitexchanges/bitcointalk/tambah_announcementaltcoin?halaman=8160 --delete-after | D6: =CONCATENATE("wget --header='Accept-Language: en-us,en;q=0.5' -T 600 http://127.0.0.1/karbitexchanges/bitcointalk/tambah_marketplacealtcoin?halaman=",Sheet9!L6," --delete-after") -> wget --header='Accept-Language: en-us,en;q=0.5' -T 600 http://127.0.0.1/karbitexchanges/bitcointalk/tambah_marketplacealtcoin?halaman=6640 --delete-after | E6: Sleep 64 | F6: Sleep 60 | L6: =Sheet9!L5-40 -> 6640
A7: =Sheet9!A6-40 -> 8120 | C7: =CONCATENATE("wget --header='Accept-Language: en-us,en;q=0.5' -T 600 http://127.0.0.1/karbitexchanges/bitcointalk/tambah_announcementaltcoin?halaman=",Sheet9!A7," --delete-after") -> wget --header='Accept-Language: en-us,en;q=0.5' -T 600 http://127.0.0.1/karbitexchanges/bitcointalk/tambah_announcementaltcoin?halaman=8120 --delete-after | D7: =CONCATENATE("wget --header='Accept-Language: en-us,en;q=0.5' -T 600 http://127.0.0.1/karbitexchanges/bitcointalk/tambah_marketplacealtcoin?halaman=",Sheet9!L7," --delete-after") -> wget --header='Accept-Language: en-us,en;q=0.5' -T 600 http://127.0.0.1/karbitexchanges/bitcointalk/tambah_marketplacealtcoin?halaman=6600 --delete-after | E7: Sleep 65 | F7: Sleep 60 | L7: =Sheet9!L6-40 -> 6600
A8: =Sheet9!A7-40 -> 8080 | C8: =CONCATENATE("wget --header='Accept-Language: en-us,en;q=0.5' -T 600 http://127.0.0.1/karbitexchanges/bitcointalk/tambah_announcementaltcoin?halaman=",Sheet9!A8," --delete-after") -> wget --header='Accept-Language: en-us,en;q=0.5' -T 600 http://127.0.0.1/karbitexchanges/bitcointalk/tambah_announcementaltcoin?halaman=8080 --delete-after | D8: =CONCATENATE("wget --header='Accept-Language: en-us,en;q=0.5' -T 600 http://127.0.0.1/karbitexchanges/bitcointalk/tambah_marketplacealtcoin?halaman=",Sheet9!L8," --delete-after") -> wget --header='Accept-Language: en-us,en;q=0.5' -T 600 http://127.0.0.1/karbitexchanges/bitcointalk/tambah_marketplacealtcoin?halaman=6560 --delete-after | E8: Sleep 66 | F8: Sleep 60 | L8: =Sheet9!L7-40 -> 6560
A9: =Sheet9!A8-40 -> 8040 | C9: =CONCATENATE("wget --header='Accept-Language: en-us,en;q=0.5' -T 600 http://127.0.0.1/karbitexchanges/bitcointalk/tambah_announcementaltcoin?halaman=",Sheet9!A9," --delete-after") -> wget --header='Accept-Language: en-us,en;q=0.5' -T 600 http://127.0.0.1/karbitexchanges/bitcointalk/tambah_announcementaltcoin?halaman=8040 --delete-after | D9: =CONCATENATE("wget --header='Accept-Language: en-us,en;q=0.5' -T 600 http://127.0.0.1/karbitexchanges/bitcointalk/tambah_marketplacealtcoin?halaman=",Sheet9!L9," --delete-after") -> wget --header='Accept-Language: en-us,en;q=0.5' -T 600 http://127.0.0.1/karbitexchanges/bitcointalk/tambah_marketplacealtcoin?halaman=6520 --delete-after | E9: Sleep 67 | F9: Sleep 60 | L9: =Sheet9!L8-40 -> 6520
A10: =Sheet9!A9-40 -> 8000 | C10: =CONCATENATE("wget --header='Accept-Language: en-us,en;q=0.5' -T 600 http://127.0.0.1/karbitexchanges/bitcointalk/tambah_announcementaltcoin?halaman=",Sheet9!A10," --delete-after") -> wget --header='Accept-Language: en-us,en;q=0.5' -T 600 http://127.0.0.1/karbitexchanges/bitcointalk/tambah_announcementaltcoin?halaman=8000 --delete-after | D10: =CONCATENATE("wget --header='Accept-Language: en-us,en;q=0.5' -T 600 http://127.0.0.1/karbitexchanges/bitcointalk/tambah_marketplacealtcoin?halaman=",Sheet9!L10," --delete-after") -> wget --header='Accept-Language: en-us,en;q=0.5' -T 600 http://127.0.0.1/karbitexchanges/bitcointalk/tambah_marketplacealtcoin?halaman=6480 --delete-after | E10: Sleep 68 | F10: Sleep 60 | L10: =Sheet9!L9-40 -> 6480
A11: =Sheet9!A10-40 -> 7960 | C11: =CONCATENATE("wget --header='Accept-Language: en-us,en;q=0.5' -T 600 http://127.0.0.1/karbitexchanges/bitcointalk/tambah_announcementaltcoin?halaman=",Sheet9!A11," --delete-after") -> wget --header='Accept-Language: en-us,en;q=0.5' -T 600 http://127.0.0.1/karbitexchanges/bitcointalk/tambah_announcementaltcoin?halaman=7960 --delete-after | D11: =CONCATENATE("wget --header='Accept-Language: en-us,en;q=0.5' -T 600 http://127.0.0.1/karbitexchanges/bitcointalk/tambah_marketplacealtcoin?halaman=",Sheet9!L11," --delete-after") -> wget --header='Accept-Language: en-us,en;q=0.5' -T 600 http://127.0.0.1/karbitexchanges/bitcointalk/tambah_marketplacealtcoin?halaman=6440 --delete-after | E11: Sleep 69 | F11: Sleep 60 | L11: =Sheet9!L10-40 -> 6440
A12: =Sheet9!A11-40 -> 7920 | C12: =CONCATENATE("wget --header='Accept-Language: en-us,en;q=0.5' -T 600 http://127.0.0.1/karbitexchanges/bitcointalk/tambah_announcementaltcoin?halaman=",Sheet9!A12," --delete-after") -> wget --header='Accept-Language: en-us,en;q=0.5' -T 600 http://127.0.0.1/karbitexchanges/bitcointalk/tambah_announcementaltcoin?halaman=7920 --delete-after | D12: =CONCATENATE("wget --header='Accept-Language: en-us,en;q=0.5' -T 600 http://127.0.0.1/karbitexchanges/bitcointalk/tambah_marketplacealtcoin?halaman=",Sheet9!L12," --delete-after") -> wget --header='Accept-Language: en-us,en;q=0.5' -T 600 http://127.0.0.1/karbitexchanges/bitcointalk/tambah_marketplacealtcoin?halaman=6400 --delete-after | E12: Sleep 70 | F12: Sleep 60 | L12: =Sheet9!L11-40 -> 6400
A13: =Sheet9!A12-40 -> 7880 | C13: =CONCATENATE("wget --header='Accept-Language: en-us,en;q=0.5' -T 600 http://127.0.0.1/karbitexchanges/bitcointalk/tambah_announcementaltcoin?halaman=",Sheet9!A13," --delete-after") -> wget --header='Accept-Language: en-us,en;q=0.5' -T 600 http://127.0.0.1/karbitexchanges/bitcointalk/tambah_announcementaltcoin?halaman=7880 --delete-after | D13: =CONCATENATE("wget --header='Accept-Language: en-us,en;q=0.5' -T 600 http://127.0.0.1/karbitexchanges/bitcointalk/tambah_marketplacealtcoin?halaman=",Sheet9!L13," --delete-after") -> wget --header='Accept-Language: en-us,en;q=0.5' -T 600 http://127.0.0.1/karbitexchanges/bitcointalk/tambah_marketplacealtcoin?halaman=6360 --delete-after | E13: Sleep 71 | F13: Sleep 60 | L13: =Sheet9!L12-40 -> 6360
... A172: =Sheet9!A171-40 -> 1520 | C172: =CONCATENATE("wget --header='Accept-Language: en-us,en;q=0.5' -T 600 http://127.0.0.1/karbitexchanges/bitcointalk/tambah_announcementaltcoin?halaman=",Sheet9!A172," --delete-after") -> wget --header='Accept-Language: en-us,en;q=0.5' -T 600 http://127.0.0.1/karbitexchanges/bitcointalk/tambah_announcementaltcoin?halaman=1520 --delete-after | D172: =CONCATENATE("wget --header='Accept-Language: en-us,en;q=0.5' -T 600 http://127.0.0.1/karbitexchanges/bitcointalk/tambah_marketplacealtcoin?halaman=",Sheet9!L172," --delete-after") -> wget --header='Accept-Language: en-us,en;q=0.5' -T 600 http://127.0.0.1/karbitexchanges/bitcointalk/tambah_marketplacealtcoin?halaman=0 --delete-after | E172: Sleep 230 | F172: Sleep 60 | L172: =Sheet9!L171-40 -> 0
A173: =Sheet9!A172-40 -> 1480 | C173: =CONCATENATE("wget --header='Accept-Language: en-us,en;q=0.5' -T 600 http://127.0.0.1/karbitexchanges/bitcointalk/tambah_announcementaltcoin?halaman=",Sheet9!A173," --delete-after") -> wget --header='Accept-Language: en-us,en;q=0.5' -T 600 http://127.0.0.1/karbitexchanges/bitcointalk/tambah_announcementaltcoin?halaman=1480 --delete-after | F173: Sleep 60
A174: =Sheet9!A173-40 -> 1440 | C174: =CONCATENATE("wget --header='Accept-Language: en-us,en;q=0.5' -T 600 http://127.0.0.1/karbitexchanges/bitcointalk/tambah_announcementaltcoin?halaman=",Sheet9!A174," --delete-after") -> wget --header='Accept-Language: en-us,en;q=0.5' -T 600 http://127.0.0.1/karbitexchanges/bitcointalk/tambah_announcementaltcoin?halaman=1440 --delete-after | F174: Sleep 60
A175: =Sheet9!A174-40 -> 1400 | C175: =CONCATENATE("wget --header='Accept-Language: en-us,en;q=0.5' -T 600 http://127.0.0.1/karbitexchanges/bitcointalk/tambah_announcementaltcoin?halaman=",Sheet9!A175," --delete-after") -> wget --header='Accept-Language: en-us,en;q=0.5' -T 600 http://127.0.0.1/karbitexchanges/bitcointalk/tambah_announcementaltcoin?halaman=1400 --delete-after | F175: Sleep 60
A176: =Sheet9!A175-40 -> 1360 | C176: =CONCATENATE("wget --header='Accept-Language: en-us,en;q=0.5' -T 600 http://127.0.0.1/karbitexchanges/bitcointalk/tambah_announcementaltcoin?halaman=",Sheet9!A176," --delete-after") -> wget --header='Accept-Language: en-us,en;q=0.5' -T 600 http://127.0.0.1/karbitexchanges/bitcointalk/tambah_announcementaltcoin?halaman=1360 --delete-after | F176: Sleep 60
A177: =Sheet9!A176-40 -> 1320 | C177: =CONCATENATE("wget --header='Accept-Language: en-us,en;q=0.5' -T 600 http://127.0.0.1/karbitexchanges/bitcointalk/tambah_announcementaltcoin?halaman=",Sheet9!A177," --delete-after") -> wget --header='Accept-Language: en-us,en;q=0.5' -T 600 http://127.0.0.1/karbitexchanges/bitcointalk/tambah_announcementaltcoin?halaman=1320 --delete-after | F177: Sleep 60
A178: =Sheet9!A177-40 -> 1280 | C178: =CONCATENATE("wget --header='Accept-Language: en-us,en;q=0.5' -T 600 http://127.0.0.1/karbitexchanges/bitcointalk/tambah_announcementaltcoin?halaman=",Sheet9!A178," --delete-after") -> wget --header='Accept-Language: en-us,en;q=0.5' -T 600 http://127.0.0.1/karbitexchanges/bitcointalk/tambah_announcementaltcoin?halaman=1280 --delete-after | F178: Sleep 60
A179: =Sheet9!A178-40 -> 1240 | C179: =CONCATENATE("wget --header='Accept-Language: en-us,en;q=0.5' -T 600 http://127.0.0.1/karbitexchanges/bitcointalk/tambah_announcementaltcoin?halaman=",Sheet9!A179," --delete-after") -> wget --header='Accept-Language: en-us,en;q=0.5' -T 600 http://127.0.0.1/karbitexchanges/bitcointalk/tambah_announcementaltcoin?halaman=1240 --delete-after | F179: Sleep 60
A180: =Sheet9!A179-40 -> 1200 | C180: =CONCATENATE("wget --header='Accept-Language: en-us,en;q=0.5' -T 600 http://127.0.0.1/karbitexchanges/bitcointalk/tambah_announcementaltcoin?halaman=",Sheet9!A180," --delete-after") -> wget --header='Accept-Language: en-us,en;q=0.5' -T 600 http://127.0.0.1/karbitexchanges/bitcointalk/tambah_announcementaltcoin?halaman=1200 --delete-after | F180: Sleep 60
A181: =Sheet9!A180-40 -> 1160 | C181: =CONCATENATE("wget --header='Accept-Language: en-us,en;q=0.5' -T 600 http://127.0.0.1/karbitexchanges/bitcointalk/tambah_announcementaltcoin?halaman=",Sheet9!A181," --delete-after") -> wget --header='Accept-Language: en-us,en;q=0.5' -T 600 http://127.0.0.1/karbitexchanges/bitcointalk/tambah_announcementaltcoin?halaman=1160 --delete-after | F181: Sleep 60
A182: =Sheet9!A181-40 -> 1120 | C182: =CONCATENATE("wget --header='Accept-Language: en-us,en;q=0.5' -T 600 http://127.0.0.1/karbitexchanges/bitcointalk/tambah_announcementaltcoin?halaman=",Sheet9!A182," --delete-after") -> wget --header='Accept-Language: en-us,en;q=0.5' -T 600 http://127.0.0.1/karbitexchanges/bitcointalk/tambah_announcementaltcoin?halaman=1120 --delete-after | F182: Sleep 60
A183: =Sheet9!A182-40 -> 1080 | C183: =CONCATENATE("wget --header='Accept-Language: en-us,en;q=0.5' -T 600 http://127.0.0.1/karbitexchanges/bitcointalk/tambah_announcementaltcoin?halaman=",Sheet9!A183," --delete-after") -> wget --header='Accept-Language: en-us,en;q=0.5' -T 600 http://127.0.0.1/karbitexchanges/bitcointalk/tambah_announcementaltcoin?halaman=1080 --delete-after | F183: Sleep 60
A184: =Sheet9!A183-40 -> 1040 | C184: =CONCATENATE("wget --header='Accept-Language: en-us,en;q=0.5' -T 600 http://127.0.0.1/karbitexchanges/bitcointalk/tambah_announcementaltcoin?halaman=",Sheet9!A184," --delete-after") -> wget --header='Accept-Language: en-us,en;q=0.5' -T 600 http://127.0.0.1/karbitexchanges/bitcointalk/tambah_announcementaltcoin?halaman=1040 --delete-after | F184: Sleep 60
... A210: =Sheet9!A209-40 -> 0 | C210: =CONCATENATE("wget --header='Accept-Language: en-us,en;q=0.5' -T 600 http://127.0.0.1/karbitexchanges/bitcointalk/tambah_announcementaltcoin?halaman=",Sheet9!A210," --delete-after") -> wget --header='Accept-Language: en-us,en;q=0.5' -T 600 http://127.0.0.1/karbitexchanges/bitcointalk/tambah_announcementaltcoin?halaman=0 --delete-after | F210: Sleep 60
